Workbook

Sheet Общая таблица
A1: Общая таблица: уровни постоянного шума и способ оповещения (СП 3.13130.2026)
A2: Объект: МБОУ ЦО № 69, Уфа, ул. Даута Юлтыя, 6. Шифр 1417/2026-АПС, СОУЭ. Ф4.1, площадь более 3000 м² — речевой способ (табл. Б.1, п. 13).
A3: Синие ячейки (D, E, K) — исходные данные. Остальное — формулы. Уровни по категориям меняются на листе «Категории». Зелёный — замена на звуковой прямо по перечню, оранжевый — с условием или по аналогии.
A5: Этаж | B5: № пом. | C5: Назначение (по экспликации) | D5: Категория (табл. В.1) | E5: Определяющее смежное пом. (для коридоров) | F5: LAeq постоянного шума, дБА | G5: Основание (табл. В.1) | H5: Мин. УЗД сигнала оповещения, дБА (п. 6.8.2) | I5: Замена речевого на звуковой (прим. 3 к табл. Б.1) | J5: Условие замены | K5: Принятый способ оповещения | L5: Разборчивость речи (п. 6.11) | M5: Примечание | N5: Уровень по категории, дБА
A6: 1 | B6: 1 | C6: Тир | D6: Спортзал, тир, раздевалки | F6: =IF($E6="",$N6,MAX($N6,INDEX($N$6:$N$225,MATCH($E6,$B$6:$B$225,0)))) -> 65 | G6: =IF($E6="",VLOOKUP($D6,Категории!$A$5:$C$17,3,FALSE()),"п. 21 — по пом. "&$E6) -> п. 18 (тир, раздевалки — по аналогии) | H6: =MAX($F6+15,65) -> 80 | I6: Нет | J6: — | K6: Речевой | L6: =IF($K6="Звуковой","не требуется (звуковой способ)",IF($F6<=65,"упрощённая оценка (п. 6.11.3)","нужен расчёт (прил. В / ПО изготовителя)")) -> упрощённая оценка (п. 6.11.3) | M6: Если стрельба ведётся в средствах защиты слуха — дополнительно световой способ (п. 6.2.9) | N6: =VLOOKUP($D6,Категории!$A$5:$C$17,2,FALSE()) -> 65
A7: 1 | B7: 2 | C7: Бойлерная | D7: Бойлерная | F7: =IF($E7="",$N7,MAX($N7,INDEX($N$6:$N$225,MATCH($E7,$B$6:$B$225,0)))) -> 80 | G7: =IF($E7="",VLOOKUP($D7,Категории!$A$5:$C$17,3,FALSE()),"п. 21 — по пом. "&$E7) -> п. 24 | H7: =MAX($F7+15,65) -> 95 | I7: Нет — не в перечне, шум не выше 85 дБА | J7: — | K7: Речевой | L7: =IF($K7="Звуковой","не требуется (звуковой способ)",IF($F7<=65,"упрощённая оценка (п. 6.11.3)","нужен расчёт (прил. В / ПО изготовителя)")) -> нужен расчёт (прил. В / ПО изготовителя) | M7: Насосы отопления | N7: =VLOOKUP($D7,Категории!$A$5:$C$17,2,FALSE()) -> 80
A8: 1 | B8: 3 | C8: Слесарная | D8: Учебные мастерские со станками | F8: =IF($E8="",$N8,MAX($N8,INDEX($N$6:$N$225,MATCH($E8,$B$6:$B$225,0)))) -> 80 | G8: =IF($E8="",VLOOKUP($D8,Категории!$A$5:$C$17,3,FALSE()),"п. 21 — по пом. "&$E8) -> по аналогии с п. 4 | H8: =MAX($F8+15,65) -> 95 | I8: Формально да (производственные помещения), но идут уроки — рекомендуется речевой | J8: Дверь с нормируемым пределом огнестойкости, шумоподавление не менее 30 дБ, доводчик (п. 6.11.4) | K8: Речевой | L8: =IF($K8="Звуковой","не требуется (звуковой способ)",IF($F8<=65,"упрощённая оценка (п. 6.11.3)","нужен расчёт (прил. В / ПО изготовителя)")) -> нужен расчёт (прил. В / ПО изготовителя) | M8: См. категорию: 60 дБА при автоматическом отключении станков (п. 6.8.7) | N8: =VLOOKUP($D8,Категории!$A$5:$C$17,2,FALSE()) -> 80
A9: 1 | B9: 4 | C9: Коридор | D9: Коммуникационные пространства | E9: 2 | F9: =IF($E9="",$N9,MAX($N9,INDEX($N$6:$N$225,MATCH($E9,$B$6:$B$225,0)))) -> 80 | G9: =IF($E9="",VLOOKUP($D9,Категории!$A$5:$C$17,3,FALSE()),"п. 21 — по пом. "&$E9) -> п. 21 — по пом. 2 | H9: =MAX($F9+15,65) -> 95 | I9: Нет | J9: — | K9: Речевой | L9: =IF($K9="Звуковой","не требуется (звуковой способ)",IF($F9<=65,"упрощённая оценка (п. 6.11.3)","нужен расчёт (прил. В / ПО изготовителя)")) -> нужен расчёт (прил. В / ПО изготовителя) | M9: Смежные: 2 бойлерная, 3 слесарная | N9: =VLOOKUP($D9,Категории!$A$5:$C$17,2,FALSE()) -> 60
A10: 1 | B10: 5 | C10: Слесарная | D10: Учебные мастерские со станками | F10: =IF($E10="",$N10,MAX($N10,INDEX($N$6:$N$225,MATCH($E10,$B$6:$B$225,0)))) -> 80 | G10: =IF($E10="",VLOOKUP($D10,Категории!$A$5:$C$17,3,FALSE()),"п. 21 — по пом. "&$E10) -> по аналогии с п. 4 | H10: =MAX($F10+15,65) -> 95 | I10: Формально да (производственные помещения), но идут уроки — рекомендуется речевой | J10: Дверь с нормируемым пределом огнестойкости, шумоподавление не менее 30 дБ, доводчик (п. 6.11.4) | K10: Речевой | L10: =IF($K10="Звуковой","не требуется (звуковой способ)",IF($F10<=65,"упрощённая оценка (п. 6.11.3)","нужен расчёт (прил. В / ПО изготовителя)")) -> нужен расчёт (прил. В / ПО изготовителя) | M10: См. категорию: 60 дБА при автоматическом отключении станков (п. 6.8.7) | N10: =VLOOKUP($D10,Категории!$A$5:$C$17,2,FALSE()) -> 80
A11: 1 | B11: 6 | C11: Слесарная | D11: Учебные мастерские со станками | F11: =IF($E11="",$N11,MAX($N11,INDEX($N$6:$N$225,MATCH($E11,$B$6:$B$225,0)))) -> 80 | G11: =IF($E11="",VLOOKUP($D11,Категории!$A$5:$C$17,3,FALSE()),"п. 21 — по пом. "&$E11) -> по аналогии с п. 4 | H11: =MAX($F11+15,65) -> 95 | I11: Формально да (производственные помещения), но идут уроки — рекомендуется речевой | J11: Дверь с нормируемым пределом огнестойкости, шумоподавление не менее 30 дБ, доводчик (п. 6.11.4) | K11: Речевой | L11: =IF($K11="Звуковой","не требуется (звуковой способ)",IF($F11<=65,"упрощённая оценка (п. 6.11.3)","нужен расчёт (прил. В / ПО изготовителя)")) -> нужен расчёт (прил. В / ПО изготовителя) | M11: См. категорию: 60 дБА при автоматическом отключении станков (п. 6.8.7) | N11: =VLOOKUP($D11,Категории!$A$5:$C$17,2,FALSE()) -> 80
A12: 1 | B12: 7 | C12: Коридор | D12: Коммуникационные пространства | E12: 6 | F12: =IF($E12="",$N12,MAX($N12,INDEX($N$6:$N$225,MATCH($E12,$B$6:$B$225,0)))) -> 80 | G12: =IF($E12="",VLOOKUP($D12,Категории!$A$5:$C$17,3,FALSE()),"п. 21 — по пом. "&$E12) -> п. 21 — по пом. 6 | H12: =MAX($F12+15,65) -> 95 | I12: Нет | J12: — | K12: Речевой | L12: =IF($K12="Звуковой","не требуется (звуковой способ)",IF($F12<=65,"упрощённая оценка (п. 6.11.3)","нужен расчёт (прил. В / ПО изготовителя)")) -> нужен расчёт (прил. В / ПО изготовителя) | M12: Смежная: 6 слесарная | N12: =VLOOKUP($D12,Категории!$A$5:$C$17,2,FALSE()) -> 60
A13: 1 | B13: 8 | C13: Лестничная клетка | D13: Коммуникационные пространства | F13: =IF($E13="",$N13,MAX($N13,INDEX($N$6:$N$225,MATCH($E13,$B$6:$B$225,0)))) -> 60 | G13: =IF($E13="",VLOOKUP($D13,Категории!$A$5:$C$17,3,FALSE()),"п. 21 — по пом. "&$E13) -> п. 21 | H13: =MAX($F13+15,65) -> 75 | I13: Нет | J13: — | K13: Речевой | L13: =IF($K13="Звуковой","не требуется (звуковой способ)",IF($F13<=65,"упрощённая оценка (п. 6.11.3)","нужен расчёт (прил. В / ПО изготовителя)")) -> упрощённая оценка (п. 6.11.3) | N13: =VLOOKUP($D13,Категории!$A$5:$C$17,2,FALSE()) -> 60
A14: 1 | B14: 9 | C14: Подсобное | D14: Вспомогательные помещения | F14: =IF($E14="",$N14,MAX($N14,INDEX($N$6:$N$225,MATCH($E14,$B$6:$B$225,0)))) -> 60 | G14: =IF($E14="",VLOOKUP($D14,Категории!$A$5:$C$17,3,FALSE()),"п. 21 — по пом. "&$E14) -> по аналогии с п. 6 | H14: =MAX($F14+15,65) -> 75 | I14: Только если по назначению кладовая или электрощитовая — уточнить | J14: Дверь с нормируемым пределом огнестойкости, шумоподавление не менее 30 дБ, доводчик (п. 6.11.4) | K14: Речевой | L14: =IF($K14="Звуковой","не требуется (звуковой способ)",IF($F14<=65,"упрощённая оценка (п. 6.11.3)","нужен расчёт (прил. В / ПО изготовителя)")) -> упрощённая оценка (п. 6.11.3) | N14: =VLOOKUP($D14,Категории!$A$5:$C$17,2,FALSE()) -> 60
A15: 1 | B15: 10 | C15: Подсобное | D15: Вспомогательные помещения | F15: =IF($E15="",$N15,MAX($N15,INDEX($N$6:$N$225,MATCH($E15,$B$6:$B$225,0)))) -> 60 | G15: =IF($E15="",VLOOKUP($D15,Категории!$A$5:$C$17,3,FALSE()),"п. 21 — по пом. "&$E15) -> по аналогии с п. 6 | H15: =MAX($F15+15,65) -> 75 | I15: Только если по назначению кладовая или электрощитовая — уточнить | J15: Дверь с нормируемым пределом огнестойкости, шумоподавление не менее 30 дБ, доводчик (п. 6.11.4) | K15: Речевой | L15: =IF($K15="Звуковой","не требуется (звуковой способ)",IF($F15<=65,"упрощённая оценка (п. 6.11.3)","нужен расчёт (прил. В / ПО изготовителя)")) -> упрощённая оценка (п. 6.11.3) | N15: =VLOOKUP($D15,Категории!$A$5:$C$17,2,FALSE()) -> 60
A16: 1 | B16: 11 | C16: Подсобное | D16: Вспомогательные помещения | F16: =IF($E16="",$N16,MAX($N16,INDEX($N$6:$N$225,MATCH($E16,$B$6:$B$225,0)))) -> 60 | G16: =IF($E16="",VLOOKUP($D16,Категории!$A$5:$C$17,3,FALSE()),"п. 21 — по пом. "&$E16) -> по аналогии с п. 6 | H16: =MAX($F16+15,65) -> 75 | I16: Только если по назначению кладовая или электрощитовая — уточнить | J16: Дверь с нормируемым пределом огнестойкости, шумоподавление не менее 30 дБ, доводчик (п. 6.11.4) | K16: Речевой | L16: =IF($K16="Звуковой","не требуется (звуковой способ)",IF($F16<=65,"упрощённая оценка (п. 6.11.3)","нужен расчёт (прил. В / ПО изготовителя)")) -> упрощённая оценка (п. 6.11.3) | N16: =VLOOKUP($D16,Категории!$A$5:$C$17,2,FALSE()) -> 60
A17: 1 | B17: 12 | C17: Подсобное | D17: Вспомогательные помещения | F17: =IF($E17="",$N17,MAX($N17,INDEX($N$6:$N$225,MATCH($E17,$B$6:$B$225,0)))) -> 60 | G17: =IF($E17="",VLOOKUP($D17,Категории!$A$5:$C$17,3,FALSE()),"п. 21 — по пом. "&$E17) -> по аналогии с п. 6 | H17: =MAX($F17+15,65) -> 75 | I17: Только если по назначению кладовая или электрощитовая — уточнить | J17: Дверь с нормируемым пределом огнестойкости, шумоподавление не менее 30 дБ, доводчик (п. 6.11.4) | K17: Речевой | L17: =IF($K17="Звуковой","не требуется (звуковой способ)",IF($F17<=65,"упрощённая оценка (п. 6.11.3)","нужен расчёт (прил. В / ПО изготовителя)")) -> упрощённая оценка (п. 6.11.3) | N17: =VLOOKUP($D17,Категории!$A$5:$C$17,2,FALSE()) -> 60
A18: 1 | B18: 13 | C18: Подсобное | D18: Вспомогательные помещения | F18: =IF($E18="",$N18,MAX($N18,INDEX($N$6:$N$225,MATCH($E18,$B$6:$B$225,0)))) -> 60 | G18: =IF($E18="",VLOOKUP($D18,Категории!$A$5:$C$17,3,FALSE()),"п. 21 — по пом. "&$E18) -> по аналогии с п. 6 | H18: =MAX($F18+15,65) -> 75 | I18: Только если по назначению кладовая или электрощитовая — уточнить | J18: Дверь с нормируемым пределом огнестойкости, шумоподавление не менее 30 дБ, доводчик (п. 6.11.4) | K18: Речевой | L18: =IF($K18="Звуковой","не требуется (звуковой способ)",IF($F18<=65,"упрощённая оценка (п. 6.11.3)","нужен расчёт (прил. В / ПО изготовителя)")) -> упрощённая оценка (п. 6.11.3) | N18: =VLOOKUP($D18,Категории!$A$5:$C$17,2,FALSE()) -> 60
A19: 1 | B19: 14 | C19: Подсобное | D19: Вспомогательные помещения | F19: =IF($E19="",$N19,MAX($N19,INDEX($N$6:$N$225,MATCH($E19,$B$6:$B$225,0)))) -> 60 | G19: =IF($E19="",VLOOKUP($D19,Категории!$A$5:$C$17,3,FALSE()),"п. 21 — по пом. "&$E19) -> по аналогии с п. 6 | H19: =MAX($F19+15,65) -> 75 | I19: Только если по назначению кладовая или электрощитовая — уточнить | J19: Дверь с нормируемым пределом огнестойкости, шумоподавление не менее 30 дБ, доводчик (п. 6.11.4) | K19: Речевой | L19: =IF($K19="Звуковой","не требуется (звуковой способ)",IF($F19<=65,"упрощённая оценка (п. 6.11.3)","нужен расчёт (прил. В / ПО изготовителя)")) -> упрощённая оценка (п. 6.11.3) | N19: =VLOOKUP($D19,Категории!$A$5:$C$17,2,FALSE()) -> 60
A20: 1 | B20: 15 | C20: Подсобное | D20: Вспомогательные помещения | F20: =IF($E20="",$N20,MAX($N20,INDEX($N$6:$N$225,MATCH($E20,$B$6:$B$225,0)))) -> 60 | G20: =IF($E20="",VLOOKUP($D20,Категории!$A$5:$C$17,3,FALSE()),"п. 21 — по пом. "&$E20) -> по аналогии с п. 6 | H20: =MAX($F20+15,65) -> 75 | I20: Только если по назначению кладовая или электрощитовая — уточнить | J20: Дверь с нормируемым пределом огнестойкости, шумоподавление не менее 30 дБ, доводчик (п. 6.11.4) | K20: Речевой | L20: =IF($K20="Звуковой","не требуется (звуковой способ)",IF($F20<=65,"упрощённая оценка (п. 6.11.3)","нужен расчёт (прил. В / ПО изготовителя)")) -> упрощённая оценка (п. 6.11.3) | N20: =VLOOKUP($D20,Категории!$A$5:$C$17,2,FALSE()) -> 60
A21: 1 | B21: 16 | C21: Подсобное | D21: Вспомогательные помещения | F21: =IF($E21="",$N21,MAX($N21,INDEX($N$6:$N$225,MATCH($E21,$B$6:$B$225,0)))) -> 60 | G21: =IF($E21="",VLOOKUP($D21,Категории!$A$5:$C$17,3,FALSE()),"п. 21 — по пом. "&$E21) -> по аналогии с п. 6 | H21: =MAX($F21+15,65) -> 75 | I21: Только если по назначению кладовая или электрощитовая — уточнить | J21: Дверь с нормируемым пределом огнестойкости, шумоподавление не менее 30 дБ, доводчик (п. 6.11.4) | K21: Речевой | L21: =IF($K21="Звуковой","не требуется (звуковой способ)",IF($F21<=65,"упрощённая оценка (п. 6.11.3)","нужен расчёт (прил. В / ПО изготовителя)")) -> упрощённая оценка (п. 6.11.3) | N21: =VLOOKUP($D21,Категории!$A$5:$C$17,2,FALSE()) -> 60
A22: 1 | B22: 17 | C22: Коридор | D22: Коммуникационные пространства | F22: =IF($E22="",$N22,MAX($N22,INDEX($N$6:$N$225,MATCH($E22,$B$6:$B$225,0)))) -> 60 | G22: =IF($E22="",VLOOKUP($D22,Категории!$A$5:$C$17,3,FALSE()),"п. 21 — по пом. "&$E22) -> п. 21 | H22: =MAX($F22+15,65) -> 75 | I22: Нет | J22: — | K22: Речевой | L22: =IF($K22="Звуковой","не требуется (звуковой способ)",IF($F22<=65,"упрощённая оценка (п. 6.11.3)","нужен расчёт (прил. В / ПО изготовителя)")) -> упрощённая оценка (п. 6.11.3) | N22: =VLOOKUP($D22,Категории!$A$5:$C$17,2,FALSE()) -> 60
A23: 1 | B23: 18 | C23: Кабинет | D23: Учебные помещения | F23: =IF($E23="",$N23,MAX($N23,INDEX($N$6:$N$225,MATCH($E23,$B$6:$B$225,0)))) -> 60 | G23: =IF($E23="",VLOOKUP($D23,Категории!$A$5:$C$17,3,FALSE()),"п. 21 — по пом. "&$E23) -> п. 6 | H23: =MAX($F23+15,65) -> 75 | I23: Нет | J23: — | K23: Речевой | L23: =IF($K23="Звуковой","не требуется (звуковой способ)",IF($F23<=65,"упрощённая оценка (п. 6.11.3)","нужен расчёт (прил. В / ПО изготовителя)")) -> упрощённая оценка (п. 6.11.3) | N23: =VLOOKUP($D23,Категории!$A$5:$C$17,2,FALSE()) -> 60
A24: 1 | B24: 19 | C24: Кабинет | D24: Учебные помещения | F24: =IF($E24="",$N24,MAX($N24,INDEX($N$6:$N$225,MATCH($E24,$B$6:$B$225,0)))) -> 60 | G24: =IF($E24="",VLOOKUP($D24,Категории!$A$5:$C$17,3,FALSE()),"п. 21 — по пом. "&$E24) -> п. 6 | H24: =MAX($F24+15,65) -> 75 | I24: Нет | J24: — | K24: Речевой | L24: =IF($K24="Звуковой","не требуется (звуковой способ)",IF($F24<=65,"упрощённая оценка (п. 6.11.3)","нужен расчёт (прил. В / ПО изготовителя)")) -> упрощённая оценка (п. 6.11.3) | N24: =VLOOKUP($D24,Категории!$A$5:$C$17,2,FALSE()) -> 60
... A26: 1 | B26: 21 | C26: Кабинет | D26: Учебные помещения | F26: =IF($E26="",$N26,MAX($N26,INDEX($N$6:$N$225,MATCH($E26,$B$6:$B$225,0)))) -> 60 | G26: =IF($E26="",VLOOKUP($D26,Категории!$A$5:$C$17,3,FALSE()),"п. 21 — по пом. "&$E26) -> п. 6 | H26: =MAX($F26+15,65) -> 75 | I26: Нет | J26: — | K26: Речевой | L26: =IF($K26="Звуковой","не требуется (звуковой способ)",IF($F26<=65,"упрощённая оценка (п. 6.11.3)","нужен расчёт (прил. В / ПО изготовителя)")) -> упрощённая оценка (п. 6.11.3) | N26: =VLOOKUP($D26,Категории!$A$5:$C$17,2,FALSE()) -> 60
A27: 1 | B27: 22 | C27: Коридор | D27: Коммуникационные пространства | E27: 1 | F27: =IF($E27="",$N27,MAX($N27,INDEX($N$6:$N$225,MATCH($E27,$B$6:$B$225,0)))) -> 65 | G27: =IF($E27="",VLOOKUP($D27,Категории!$A$5:$C$17,3,FALSE()),"п. 21 — по пом. "&$E27) -> п. 21 — по пом. 1 | H27: =MAX($F27+15,65) -> 80 | I27: Нет | J27: — | K27: Речевой | L27: =IF($K27="Звуковой","не требуется (звуковой способ)",IF($F27<=65,"упрощённая оценка (п. 6.11.3)","нужен расчёт (прил. В / ПО изготовителя)")) -> упрощённая оценка (п. 6.11.3) | M27: Смежный: 1 тир | N27: =VLOOKUP($D27,Категории!$A$5:$C$17,2,FALSE()) -> 60
A28: 1 | B28: 23 | C28: Коридор | D28: Коммуникационные пространства | F28: =IF($E28="",$N28,MAX($N28,INDEX($N$6:$N$225,MATCH($E28,$B$6:$B$225,0)))) -> 60 | G28: =IF($E28="",VLOOKUP($D28,Категории!$A$5:$C$17,3,FALSE()),"п. 21 — по пом. "&$E28) -> п. 21 | H28: =MAX($F28+15,65) -> 75 | I28: Нет | J28: — | K28: Речевой | L28: =IF($K28="Звуковой","не требуется (звуковой способ)",IF($F28<=65,"упрощённая оценка (п. 6.11.3)","нужен расчёт (прил. В / ПО изготовителя)")) -> упрощённая оценка (п. 6.11.3) | N28: =VLOOKUP($D28,Категории!$A$5:$C$17,2,FALSE()) -> 60
A29: 1 | B29: 24 | C29: Кабинет | D29: Учебные помещения | F29: =IF($E29="",$N29,MAX($N29,INDEX($N$6:$N$225,MATCH($E29,$B$6:$B$225,0)))) -> 60 | G29: =IF($E29="",VLOOKUP($D29,Категории!$A$5:$C$17,3,FALSE()),"п. 21 — по пом. "&$E29) -> п. 6 | H29: =MAX($F29+15,65) -> 75 | I29: Нет | J29: — | K29: Речевой | L29: =IF($K29="Звуковой","не требуется (звуковой способ)",IF($F29<=65,"упрощённая оценка (п. 6.11.3)","нужен расчёт (прил. В / ПО изготовителя)")) -> упрощённая оценка (п. 6.11.3) | N29: =VLOOKUP($D29,Категории!$A$5:$C$17,2,FALSE()) -> 60
A30: 1 | B30: 25 | C30: Кабинет | D30: Учебные помещения | F30: =IF($E30="",$N30,MAX($N30,INDEX($N$6:$N$225,MATCH($E30,$B$6:$B$225,0)))) -> 60 | G30: =IF($E30="",VLOOKUP($D30,Категории!$A$5:$C$17,3,FALSE()),"п. 21 — по пом. "&$E30) -> п. 6 | H30: =MAX($F30+15,65) -> 75 | I30: Нет | J30: — | K30: Речевой | L30: =IF($K30="Звуковой","не требуется (звуковой способ)",IF($F30<=65,"упрощённая оценка (п. 6.11.3)","нужен расчёт (прил. В / ПО изготовителя)")) -> упрощённая оценка (п. 6.11.3) | N30: =VLOOKUP($D30,Категории!$A$5:$C$17,2,FALSE()) -> 60
A31: 1 | B31: 26 | C31: Кабинет | D31: Учебные помещения | F31: =IF($E31="",$N31,MAX($N31,INDEX($N$6:$N$225,MATCH($E31,$B$6:$B$225,0)))) -> 60 | G31: =IF($E31="",VLOOKUP($D31,Категории!$A$5:$C$17,3,FALSE()),"п. 21 — по пом. "&$E31) -> п. 6 | H31: =MAX($F31+15,65) -> 75 | I31: Нет | J31: — | K31: Речевой | L31: =IF($K31="Звуковой","не требуется (звуковой способ)",IF($F31<=65,"упрощённая оценка (п. 6.11.3)","нужен расчёт (прил. В / ПО изготовителя)")) -> упрощённая оценка (п. 6.11.3) | N31: =VLOOKUP($D31,Категории!$A$5:$C$17,2,FALSE()) -> 60
A32: 1 | B32: 27 | C32: Кабинет | D32: Учебные помещения | F32: =IF($E32="",$N32,MAX($N32,INDEX($N$6:$N$225,MATCH($E32,$B$6:$B$225,0)))) -> 60 | G32: =IF($E32="",VLOOKUP($D32,Категории!$A$5:$C$17,3,FALSE()),"п. 21 — по пом. "&$E32) -> п. 6 | H32: =MAX($F32+15,65) -> 75 | I32: Нет | J32: — | K32: Речевой | L32: =IF($K32="Звуковой","не требуется (звуковой способ)",IF($F32<=65,"упрощённая оценка (п. 6.11.3)","нужен расчёт (прил. В / ПО изготовителя)")) -> упрощённая оценка (п. 6.11.3) | N32: =VLOOKUP($D32,Категории!$A$5:$C$17,2,FALSE()) -> 60
A33: 1 | B33: 28 | C33: Коридор | D33: Коммуникационные пространства | F33: =IF($E33="",$N33,MAX($N33,INDEX($N$6:$N$225,MATCH($E33,$B$6:$B$225,0)))) -> 60 | G33: =IF($E33="",VLOOKUP($D33,Категории!$A$5:$C$17,3,FALSE()),"п. 21 — по пом. "&$E33) -> п. 21 | H33: =MAX($F33+15,65) -> 75 | I33: Нет | J33: — | K33: Речевой | L33: =IF($K33="Звуковой","не требуется (звуковой способ)",IF($F33<=65,"упрощённая оценка (п. 6.11.3)","нужен расчёт (прил. В / ПО изготовителя)")) -> упрощённая оценка (п. 6.11.3) | N33: =VLOOKUP($D33,Категории!$A$5:$C$17,2,FALSE()) -> 60
A34: 1 | B34: 29 | C34: Класс | D34: Учебные помещения | F34: =IF($E34="",$N34,MAX($N34,INDEX($N$6:$N$225,MATCH($E34,$B$6:$B$225,0)))) -> 60 | G34: =IF($E34="",VLOOKUP($D34,Категории!$A$5:$C$17,3,FALSE()),"п. 21 — по пом. "&$E34) -> п. 6 | H34: =MAX($F34+15,65) -> 75 | I34: Нет | J34: — | K34: Речевой | L34: =IF($K34="Звуковой","не требуется (звуковой способ)",IF($F34<=65,"упрощённая оценка (п. 6.11.3)","нужен расчёт (прил. В / ПО изготовителя)")) -> упрощённая оценка (п. 6.11.3) | N34: =VLOOKUP($D34,Категории!$A$5:$C$17,2,FALSE()) -> 60
A35: 1 | B35: 30 | C35: Зал | D35: Многоцелевые залы | F35: =IF($E35="",$N35,MAX($N35,INDEX($N$6:$N$225,MATCH($E35,$B$6:$B$225,0)))) -> 70 | G35: =IF($E35="",VLOOKUP($D35,Категории!$A$5:$C$17,3,FALSE()),"п. 21 — по пом. "&$E35) -> п. 16 | H35: =MAX($F35+15,65) -> 85 | I35: Нет | J35: — | K35: Речевой | L35: =IF($K35="Звуковой","не требуется (звуковой способ)",IF($F35<=65,"упрощённая оценка (п. 6.11.3)","нужен расчёт (прил. В / ПО изготовителя)")) -> нужен расчёт (прил. В / ПО изготовителя) | M35: Назначение уточнить; принят как многоцелевой зал | N35: =VLOOKUP($D35,Категории!$A$5:$C$17,2,FALSE()) -> 70
A36: 1 | B36: 31 | C36: Комната охраны | D36: Пост охраны | F36: =IF($E36="",$N36,MAX($N36,INDEX($N$6:$N$225,MATCH($E36,$B$6:$B$225,0)))) -> 70 | G36: =IF($E36="",VLOOKUP($D36,Категории!$A$5:$C$17,3,FALSE()),"п. 21 — по пом. "&$E36) -> п. 2 | H36: =MAX($F36+15,65) -> 85 | I36: Нет | J36: — | K36: Речевой | L36: =IF($K36="Звуковой","не требуется (звуковой способ)",IF($F36<=65,"упрощённая оценка (п. 6.11.3)","нужен расчёт (прил. В / ПО изготовителя)")) -> нужен расчёт (прил. В / ПО изготовителя) | M36: Пожарный пост, аварийный микрофон | N36: =VLOOKUP($D36,Категории!$A$5:$C$17,2,FALSE()) -> 70
A37: 1 | B37: 32 | C37: Коридор | D37: Коммуникационные пространства | E37: 30 | F37: =IF($E37="",$N37,MAX($N37,INDEX($N$6:$N$225,MATCH($E37,$B$6:$B$225,0)))) -> 70 | G37: =IF($E37="",VLOOKUP($D37,Категории!$A$5:$C$17,3,FALSE()),"п. 21 — по пом. "&$E37) -> п. 21 — по пом. 30 | H37: =MAX($F37+15,65) -> 85 | I37: Нет | J37: — | K37: Речевой | L37: =IF($K37="Звуковой","не требуется (звуковой способ)",IF($F37<=65,"упрощённая оценка (п. 6.11.3)","нужен расчёт (прил. В / ПО изготовителя)")) -> нужен расчёт (прил. В / ПО изготовителя) | M37: Смежные: 30 зал, 31 комната охраны | N37: =VLOOKUP($D37,Категории!$A$5:$C$17,2,FALSE()) -> 60
A38: 1 | B38: 33 | C38: Тамбур | D38: Коммуникационные пространства | F38: =IF($E38="",$N38,MAX($N38,INDEX($N$6:$N$225,MATCH($E38,$B$6:$B$225,0)))) -> 60 | G38: =IF($E38="",VLOOKUP($D38,Категории!$A$5:$C$17,3,FALSE()),"п. 21 — по пом. "&$E38) -> п. 21 | H38: =MAX($F38+15,65) -> 75 | I38: Нет | J38: — | K38: Речевой | L38: =IF($K38="Звуковой","не требуется (звуковой способ)",IF($F38<=65,"упрощённая оценка (п. 6.11.3)","нужен расчёт (прил. В / ПО изготовителя)")) -> упрощённая оценка (п. 6.11.3) | M38: При площади менее 4 м² оповещение можно не предусматривать (п. 6.1.3) | N38: =VLOOKUP($D38,Категории!$A$5:$C$17,2,FALSE()) -> 60
A39: 1 | B39: 34 | C39: Коридор | D39: Коммуникационные пространства | F39: =IF($E39="",$N39,MAX($N39,INDEX($N$6:$N$225,MATCH($E39,$B$6:$B$225,0)))) -> 60 | G39: =IF($E39="",VLOOKUP($D39,Категории!$A$5:$C$17,3,FALSE()),"п. 21 — по пом. "&$E39) -> п. 21 | H39: =MAX($F39+15,65) -> 75 | I39: Нет | J39: — | K39: Речевой | L39: =IF($K39="Звуковой","не требуется (звуковой способ)",IF($F39<=65,"упрощённая оценка (п. 6.11.3)","нужен расчёт (прил. В / ПО изготовителя)")) -> упрощённая оценка (п. 6.11.3) | N39: =VLOOKUP($D39,Категории!$A$5:$C$17,2,FALSE()) -> 60
A40: 1 | B40: 36 | C40: Раздевалка | D40: Спортзал, тир, раздевалки | F40: =IF($E40="",$N40,MAX($N40,INDEX($N$6:$N$225,MATCH($E40,$B$6:$B$225,0)))) -> 65 | G40: =IF($E40="",VLOOKUP($D40,Категории!$A$5:$C$17,3,FALSE()),"п. 21 — по пом. "&$E40) -> п. 18 (тир, раздевалки — по аналогии) | H40: =MAX($F40+15,65) -> 80 | I40: Нет | J40: — | K40: Речевой | L40: =IF($K40="Звуковой","не требуется (звуковой способ)",IF($F40<=65,"упрощённая оценка (п. 6.11.3)","нужен расчёт (прил. В / ПО изготовителя)")) -> упрощённая оценка (п. 6.11.3) | N40: =VLOOKUP($D40,Категории!$A$5:$C$17,2,FALSE()) -> 65
A41: 1 | B41: 37 | C41: Лестничная клетка | D41: Коммуникационные пространства | F41: =IF($E41="",$N41,MAX($N41,INDEX($N$6:$N$225,MATCH($E41,$B$6:$B$225,0)))) -> 60 | G41: =IF($E41="",VLOOKUP($D41,Категории!$A$5:$C$17,3,FALSE()),"п. 21 — по пом. "&$E41) -> п. 21 | H41: =MAX($F41+15,65) -> 75 | I41: Нет | J41: — | K41: Речевой | L41: =IF($K41="Звуковой","не требуется (звуковой способ)",IF($F41<=65,"упрощённая оценка (п. 6.11.3)","нужен расчёт (прил. В / ПО изготовителя)")) -> упрощённая оценка (п. 6.11.3) | N41: =VLOOKUP($D41,Категории!$A$5:$C$17,2,FALSE()) -> 60
A42: 1 | B42: 38 | C42: Коридор | D42: Коммуникационные пространства | E42: 36 | F42: =IF($E42="",$N42,MAX($N42,INDEX($N$6:$N$225,MATCH($E42,$B$6:$B$225,0)))) -> 65 | G42: =IF($E42="",VLOOKUP($D42,Категории!$A$5:$C$17,3,FALSE()),"п. 21 — по пом. "&$E42) -> п. 21 — по пом. 36 | H42: =MAX($F42+15,65) -> 80 | I42: Нет | J42: — | K42: Речевой | L42: =IF($K42="Звуковой","не требуется (звуковой способ)",IF($F42<=65,"упрощённая оценка (п. 6.11.3)","нужен расчёт (прил. В / ПО изготовителя)")) -> упрощённая оценка (п. 6.11.3) | M42: Смежная: 36 раздевалка | N42: =VLOOKUP($D42,Категории!$A$5:$C$17,2,FALSE()) -> 60
...

Sheet Замена на звуковой
A1: Помещения, где речевой способ можно заменить на звуковой (прим. 3 к табл. Б.1 СП 3.13130.2026)
A2: Обязательное условие для любой замены (п. 6.11.4): помещение отделено от помещений с речевым оповещением дверью с нормируемым пределом огнестойкости, шумоподавлением не менее 30 дБ и доводчиком. При обычной двери замена не допускается.
A4: Этаж | B4: № пом. | C4: Назначение | D4: Основание замены | E4: Рекомендация | F4: LAeq, дБА
A5: 1 | B5: 45 | C5: Кладовая | D5: Да — кладовые | E5: Можно при соответствии двери; рекомендуется оставить речевой | F5: =INDEX('Общая таблица'!$F$6:$F$225,MATCH("45",'Общая таблица'!$B$6:$B$225,0)) -> 60
A6: 1 | B6: 58 | C6: Кладовая | D6: Да — кладовые | E6: Можно при соответствии двери; рекомендуется оставить речевой | F6: =INDEX('Общая таблица'!$F$6:$F$225,MATCH("58",'Общая таблица'!$B$6:$B$225,0)) -> 60
A7: 1 | B7: 63 | C7: Холодильная камера | D7: Да — помещения холодильных камер | E7: Звуковой, если дверь отвечает п. 6.11.4 | F7: =INDEX('Общая таблица'!$F$6:$F$225,MATCH("63",'Общая таблица'!$B$6:$B$225,0)) -> 70
A8: 2 | B8: 97 | C8: Кладовая | D8: Да — кладовые | E8: Можно при соответствии двери; рекомендуется оставить речевой | F8: =INDEX('Общая таблица'!$F$6:$F$225,MATCH("97",'Общая таблица'!$B$6:$B$225,0)) -> 60
A9: 2 | B9: 132 | C9: Венткамера | D9: Да — венткамеры | E9: Звуковой (рекомендуется) | F9: =INDEX('Общая таблица'!$F$6:$F$225,MATCH("132",'Общая таблица'!$B$6:$B$225,0)) -> 80
A10: 3 | B10: 152 | C10: Кладовая | D10: Да — кладовые | E10: Можно при соответствии двери; рекомендуется оставить речевой | F10: =INDEX('Общая таблица'!$F$6:$F$225,MATCH("152",'Общая таблица'!$B$6:$B$225,0)) -> 60
A11: 4 | B11: 190 | C11: Кладовая | D11: Да — кладовые | E11: Можно при соответствии двери; рекомендуется оставить речевой | F11: =INDEX('Общая таблица'!$F$6:$F$225,MATCH("190",'Общая таблица'!$B$6:$B$225,0)) -> 60
A12: 1 | B12: 3 | C12: Слесарная | D12: Формально да (производственные помещения), но идут уроки — рекомендуется речевой | E12: Речевой (рекомендуется) | F12: =INDEX('Общая таблица'!$F$6:$F$225,MATCH("3",'Общая таблица'!$B$6:$B$225,0)) -> 80
A13: 1 | B13: 5 | C13: Слесарная | D13: Формально да (производственные помещения), но идут уроки — рекомендуется речевой | E13: Речевой (рекомендуется) | F13: =INDEX('Общая таблица'!$F$6:$F$225,MATCH("5",'Общая таблица'!$B$6:$B$225,0)) -> 80
A14: 1 | B14: 6 | C14: Слесарная | D14: Формально да (производственные помещения), но идут уроки — рекомендуется речевой | E14: Речевой (рекомендуется) | F14: =INDEX('Общая таблица'!$F$6:$F$225,MATCH("6",'Общая таблица'!$B$6:$B$225,0)) -> 80
A15: 1 | B15: 9 | C15: Подсобное | D15: Только если по назначению кладовая или электрощитовая — уточнить | E15: Только с обоснованием / уточнением; рекомендуется оставить речевой | F15: =INDEX('Общая таблица'!$F$6:$F$225,MATCH("9",'Общая таблица'!$B$6:$B$225,0)) -> 60
A16: 1 | B16: 10 | C16: Подсобное | D16: Только если по назначению кладовая или электрощитовая — уточнить | E16: Только с обоснованием / уточнением; рекомендуется оставить речевой | F16: =INDEX('Общая таблица'!$F$6:$F$225,MATCH("10",'Общая таблица'!$B$6:$B$225,0)) -> 60
A17: 1 | B17: 11 | C17: Подсобное | D17: Только если по назначению кладовая или электрощитовая — уточнить | E17: Только с обоснованием / уточнением; рекомендуется оставить речевой | F17: =INDEX('Общая таблица'!$F$6:$F$225,MATCH("11",'Общая таблица'!$B$6:$B$225,0)) -> 60
A18: 1 | B18: 12 | C18: Подсобное | D18: Только если по назначению кладовая или электрощитовая — уточнить | E18: Только с обоснованием / уточнением; рекомендуется оставить речевой | F18: =INDEX('Общая таблица'!$F$6:$F$225,MATCH("12",'Общая таблица'!$B$6:$B$225,0)) -> 60
A19: 1 | B19: 13 | C19: Подсобное | D19: Только если по назначению кладовая или электрощитовая — уточнить | E19: Только с обоснованием / уточнением; рекомендуется оставить речевой | F19: =INDEX('Общая таблица'!$F$6:$F$225,MATCH("13",'Общая таблица'!$B$6:$B$225,0)) -> 60
A20: 1 | B20: 14 | C20: Подсобное | D20: Только если по назначению кладовая или электрощитовая — уточнить | E20: Только с обоснованием / уточнением; рекомендуется оставить речевой | F20: =INDEX('Общая таблица'!$F$6:$F$225,MATCH("14",'Общая таблица'!$B$6:$B$225,0)) -> 60
A21: 1 | B21: 15 | C21: Подсобное | D21: Только если по назначению кладовая или электрощитовая — уточнить | E21: Только с обоснованием / уточнением; рекомендуется оставить речевой | F21: =INDEX('Общая таблица'!$F$6:$F$225,MATCH("15",'Общая таблица'!$B$6:$B$225,0)) -> 60
A22: 1 | B22: 16 | C22: Подсобное | D22: Только если по назначению кладовая или электрощитовая — уточнить | E22: Только с обоснованием / уточнением; рекомендуется оставить речевой | F22: =INDEX('Общая таблица'!$F$6:$F$225,MATCH("16",'Общая таблица'!$B$6:$B$225,0)) -> 60
A23: 1 | B23: 62 | C23: Склад | D23: По аналогии с кладовыми — обосновать в ПЗ | E23: Только с обоснованием / уточнением; рекомендуется оставить речевой | F23: =INDEX('Общая таблица'!$F$6:$F$225,MATCH("62",'Общая таблица'!$B$6:$B$225,0)) -> 60
A24: 1 | B24: 70 | C24: Подсобное | D24: Только если по назначению кладовая или электрощитовая — уточнить | E24: Только с обоснованием / уточнением; рекомендуется оставить речевой | F24: =INDEX('Общая таблица'!$F$6:$F$225,MATCH("70",'Общая таблица'!$B$6:$B$225,0)) -> 60
A25: 1 | B25: 74 | C25: Мастерская | D25: Формально да (производственные помещения), но идут уроки — рекомендуется речевой | E25: Речевой (рекомендуется) | F25: =INDEX('Общая таблица'!$F$6:$F$225,MATCH("74",'Общая таблица'!$B$6:$B$225,0)) -> 80
A26: 1 | B26: 76 | C26: Инструментальная | D26: По аналогии с кладовыми — обосновать в ПЗ | E26: Только с обоснованием / уточнением; рекомендуется оставить речевой | F26: =INDEX('Общая таблица'!$F$6:$F$225,MATCH("76",'Общая таблица'!$B$6:$B$225,0)) -> 60
A27: 1 | B27: 80 | C27: Подсобное | D27: Только если по назначению кладовая или электрощитовая — уточнить | E27: Только с обоснованием / уточнением; рекомендуется оставить речевой | F27: =INDEX('Общая таблица'!$F$6:$F$225,MATCH("80",'Общая таблица'!$B$6:$B$225,0)) -> 60
A28: 2 | B28: 124 | C28: Архив | D28: По аналогии с кладовыми — обосновать в ПЗ | E28: Только с обоснованием / уточнением; рекомендуется оставить речевой | F28: =INDEX('Общая таблица'!$F$6:$F$225,MATCH("124",'Общая таблица'!$B$6:$B$225,0)) -> 60
A29: 2 | B29: 125 | C29: Архив | D29: По аналогии с кладовыми — обосновать в ПЗ | E29: Только с обоснованием / уточнением; рекомендуется оставить речевой | F29: =INDEX('Общая таблица'!$F$6:$F$225,MATCH("125",'Общая таблица'!$B$6:$B$225,0)) -> 60
A30: 2 | B30: 131 | C30: Подсобное | D30: Только если по назначению кладовая или электрощитовая — уточнить | E30: Только с обоснованием / уточнением; рекомендуется оставить речевой | F30: =INDEX('Общая таблица'!$F$6:$F$225,MATCH("131",'Общая таблица'!$B$6:$B$225,0)) -> 60
A31: 2 | B31: 133 | C31: Подсобное | D31: Только если по назначению кладовая или электрощитовая — уточнить | E31: Только с обоснованием / уточнением; рекомендуется оставить речевой | F31: =INDEX('Общая таблица'!$F$6:$F$225,MATCH("133",'Общая таблица'!$B$6:$B$225,0)) -> 60
A32: 2 | B32: 135 | C32: Подсобное | D32: Только если по назначению кладовая или электрощитовая — уточнить | E32: Только с обоснованием / уточнением; рекомендуется оставить речевой | F32: =INDEX('Общая таблица'!$F$6:$F$225,MATCH("135",'Общая таблица'!$B$6:$B$225,0)) -> 60
A33: 2 | B33: 136 | C33: Подсобное | D33: Только если по назначению кладовая или электрощитовая — уточнить | E33: Только с обоснованием / уточнением; рекомендуется оставить речевой | F33: =INDEX('Общая таблица'!$F$6:$F$225,MATCH("136",'Общая таблица'!$B$6:$B$225,0)) -> 60
A35: Нельзя заменить: санузлы (в школе общественные), моечная 64 (пищеблок общественного питания), бойлерная 2 (нет в перечне, шум не выше 85 дБА), классы, кабинеты, залы, коридоры, лестницы.
A36: Пунктов перечня нет в здании: чердаки, технические этажи, помещения с газовым/аэрозольным/порошковым АУП, помещения с шумом выше 85 дБА, электрощитовые, машинные отделения лифтов. Если найдутся — туда тоже можно звуковой.

Sheet Категории
A1: Справочник: УЗД постоянного шума по табл. В.1 СП 3.13130.2026
A2: Синие значения в столбце B можно менять — лист «Общая таблица» пересчитается.
A4: Категория помещений | B4: LAeq, дБА | C4: Позиция табл. В.1 | D4: Обоснование
A5: Учебные помещения | B5: 60 | C5: п. 6 | D5: Классные помещения, учебные кабинеты, учительские, читальные залы библиотек
A6: Вспомогательные помещения | B6: 60 | C6: по аналогии с п. 6 | D6: Подсобные, кладовые, склад, архив, инструментальная, бытовка, приёмная — помещения образовательной организации; в табл. В.1 прямой позиции нет
A7: Медицинские помещения | B7: 50 | C7: п. 5 | D7: Кабинеты врачей медицинских организаций
A8: Санузлы | B8: 55 | C8: п. 28 | D8: Ванные, душевые, санузлы
A9: Спортзал, тир, раздевалки | B9: 65 | C9: п. 18 (тир, раздевалки — по аналогии) | D9: Спортивные залы
A10: Обеденный зал | B10: 65 | C10: п. 12 | D10: Залы кафе, ресторанов
A11: Пищеблок | B11: 70 | C11: по аналогии с п. 26 | D11: Кухни ресторанов и кафе (моечная, холодильная камера)
A12: Многоцелевые залы | B12: 70 | C12: п. 16 | D12: Многоцелевые залы (актовый зал, зал)
A13: Пост охраны | B13: 70 | C13: п. 2 | D13: Рабочие помещения диспетчерских служб с речевой связью по телефону
A14: Учебные мастерские со станками | B14: 80 | C14: по аналогии с п. 4 | D14: Помещения с постоянными рабочими местами производственных предприятий; станки учтены как постоянный шум (п. 6.8.7). При автоматическом отключении станков по сигналу «Пожар» не более чем за 60 с принять 60 дБА
A15: Бойлерная | B15: 80 | C15: п. 24 | D15: Помещения компрессорных и насосных (постоянно или попеременно работающих)
A16: Венткамера | B16: 80 | C16: п. 23 | D16: Помещения для вентмашин
A17: Коммуникационные пространства | B17: 60 | C17: п. 21 | D17: Коридоры, лестничные клетки, тамбуры: по уровню шума в помещениях, имеющих прямое сообщение. По умолчанию — учебные помещения (60); если рядом более шумное помещение — по нему (столбец E)

Sheet Пояснения
A1: Пояснения к общей таблице
A3: Источник
A4: СП 3.13130.2026 (введён с 01.06.2026), приложение В, п. В.2.1 и таблица В.1. УЗД постоянного шума принимается по измерениям или по справочным данным табл. В.1; по заданию на проектирование значения можно корректировать в большую сторону.
A5: Примечание 2 к табл. В.1: фактический УЗД постоянного шума уточняется при вводе системы в эксплуатацию.
A6: П. 6.8.6: уровни постоянного шума должны быть отражены в проектной документации.
A8: Как выбраны значения
A9: 1. Где назначение помещения прямо есть в табл. В.1 — взята эта позиция.
A10: 2. Где прямой позиции нет — ближайшая по смыслу; в спорных случаях выбиралось большее значение (это допускает п. В.2.1).
A11: 3. Коридоры, лестничные клетки, тамбуры (п. 21) — по шуму в смежных помещениях: по умолчанию 60 дБА (учебные помещения); если в коридор выходит более шумное помещение — по нему (лист «Общая таблица», столбец E). Смежность определена по планам листов 6–9.
A12: 4. Мастерские и слесарные приняты 80 дБА: станки считаются постоянным шумом, если их нельзя автоматически остановить при пожаре за 60 с (п. 6.8.7). Если в проект добавить отключение станков по сигналу «Пожар», на листе «Категории» поменять 80 на 60 — мастерские и коридоры 7, 75, 79, 81, 84, 85 пересчитаются. Коридор 4 останется 80 (смежная бойлерная).
A14: Что следует из уровня шума
A15: П. 6.8.2: сигнал оповещения должен превышать постоянный шум не менее чем на 15 дБ и быть не ниже 65 дБА в любой точке на высоте 1,5 м (столбец H общей таблицы).
... A32: Принято: звуковой — венткамера 132 и холодильная камера 63 (при соответствии двери). В остальных помещениях речевой: замена потребовала бы противопожарных дверей и отдельной линии питания 24 В для звуковых оповещателей.
