Workbook

Sheet Уровни шума
A1: Уровни постоянного шума в помещениях (СП 3.13130.2026, прил. В, табл. В.1)
A2: Объект: МБОУ ЦО № 69, Уфа, ул. Даута Юлтыя, 6. Шифр 1417/2026-АПС, СОУЭ
A3: Синие ячейки (D, E) — исходные данные. Остальное — формулы. Уровни по категориям меняются на листе «Категории».
A5: Этаж | B5: № пом. | C5: Назначение (по экспликации) | D5: Категория (табл. В.1) | E5: Определяющее смежное пом. (для коридоров) | F5: LAeq постоянного шума, дБА | G5: Основание (табл. В.1) | H5: Мин. УЗД сигнала оповещения, дБА (п. 6.8.2) | I5: Разборчивость речи (п. 6.11) | J5: Примечание | K5: Уровень по категории, дБА
A6: 1 | B6: 1 | C6: Тир | D6: Спортзал, тир, раздевалки | F6: =IF($E6="",$K6,MAX($K6,INDEX($K$6:$K$225,MATCH($E6,$B$6:$B$225,0)))) -> 65 | G6: =IF($E6="",VLOOKUP($D6,Категории!$A$5:$C$17,3,FALSE()),"п. 21 — по пом. "&$E6) -> п. 18 (тир, раздевалки — по аналогии) | H6: =MAX($F6+15,65) -> 80 | I6: =IF($F6<=65,"упрощённая оценка (п. 6.11.3)","нужен расчёт (прил. В / ПО изготовителя)") -> упрощённая оценка (п. 6.11.3) | J6: Если стрельба ведётся в средствах защиты слуха — дополнительно световой способ (п. 6.2.9) | K6: =VLOOKUP($D6,Категории!$A$5:$C$17,2,FALSE()) -> 65
A7: 1 | B7: 2 | C7: Бойлерная | D7: Бойлерная | F7: =IF($E7="",$K7,MAX($K7,INDEX($K$6:$K$225,MATCH($E7,$B$6:$B$225,0)))) -> 80 | G7: =IF($E7="",VLOOKUP($D7,Категории!$A$5:$C$17,3,FALSE()),"п. 21 — по пом. "&$E7) -> п. 24 | H7: =MAX($F7+15,65) -> 95 | I7: =IF($F7<=65,"упрощённая оценка (п. 6.11.3)","нужен расчёт (прил. В / ПО изготовителя)") -> нужен расчёт (прил. В / ПО изготовителя) | J7: Насосы отопления | K7: =VLOOKUP($D7,Категории!$A$5:$C$17,2,FALSE()) -> 80
A8: 1 | B8: 3 | C8: Слесарная | D8: Учебные мастерские со станками | F8: =IF($E8="",$K8,MAX($K8,INDEX($K$6:$K$225,MATCH($E8,$B$6:$B$225,0)))) -> 80 | G8: =IF($E8="",VLOOKUP($D8,Категории!$A$5:$C$17,3,FALSE()),"п. 21 — по пом. "&$E8) -> по аналогии с п. 4 | H8: =MAX($F8+15,65) -> 95 | I8: =IF($F8<=65,"упрощённая оценка (п. 6.11.3)","нужен расчёт (прил. В / ПО изготовителя)") -> нужен расчёт (прил. В / ПО изготовителя) | J8: См. категорию: 60 дБА при автоматическом отключении станков (п. 6.8.7) | K8: =VLOOKUP($D8,Категории!$A$5:$C$17,2,FALSE()) -> 80
A9: 1 | B9: 4 | C9: Коридор | D9: Коммуникационные пространства | E9: 2 | F9: =IF($E9="",$K9,MAX($K9,INDEX($K$6:$K$225,MATCH($E9,$B$6:$B$225,0)))) -> 80 | G9: =IF($E9="",VLOOKUP($D9,Категории!$A$5:$C$17,3,FALSE()),"п. 21 — по пом. "&$E9) -> п. 21 — по пом. 2 | H9: =MAX($F9+15,65) -> 95 | I9: =IF($F9<=65,"упрощённая оценка (п. 6.11.3)","нужен расчёт (прил. В / ПО изготовителя)") -> нужен расчёт (прил. В / ПО изготовителя) | J9: Смежные: 2 бойлерная, 3 слесарная | K9: =VLOOKUP($D9,Категории!$A$5:$C$17,2,FALSE()) -> 60
A10: 1 | B10: 5 | C10: Слесарная | D10: Учебные мастерские со станками | F10: =IF($E10="",$K10,MAX($K10,INDEX($K$6:$K$225,MATCH($E10,$B$6:$B$225,0)))) -> 80 | G10: =IF($E10="",VLOOKUP($D10,Категории!$A$5:$C$17,3,FALSE()),"п. 21 — по пом. "&$E10) -> по аналогии с п. 4 | H10: =MAX($F10+15,65) -> 95 | I10: =IF($F10<=65,"упрощённая оценка (п. 6.11.3)","нужен расчёт (прил. В / ПО изготовителя)") -> нужен расчёт (прил. В / ПО изготовителя) | J10: См. категорию: 60 дБА при автоматическом отключении станков (п. 6.8.7) | K10: =VLOOKUP($D10,Категории!$A$5:$C$17,2,FALSE()) -> 80
A11: 1 | B11: 6 | C11: Слесарная | D11: Учебные мастерские со станками | F11: =IF($E11="",$K11,MAX($K11,INDEX($K$6:$K$225,MATCH($E11,$B$6:$B$225,0)))) -> 80 | G11: =IF($E11="",VLOOKUP($D11,Категории!$A$5:$C$17,3,FALSE()),"п. 21 — по пом. "&$E11) -> по аналогии с п. 4 | H11: =MAX($F11+15,65) -> 95 | I11: =IF($F11<=65,"упрощённая оценка (п. 6.11.3)","нужен расчёт (прил. В / ПО изготовителя)") -> нужен расчёт (прил. В / ПО изготовителя) | J11: См. категорию: 60 дБА при автоматическом отключении станков (п. 6.8.7) | K11: =VLOOKUP($D11,Категории!$A$5:$C$17,2,FALSE()) -> 80
A12: 1 | B12: 7 | C12: Коридор | D12: Коммуникационные пространства | E12: 6 | F12: =IF($E12="",$K12,MAX($K12,INDEX($K$6:$K$225,MATCH($E12,$B$6:$B$225,0)))) -> 80 | G12: =IF($E12="",VLOOKUP($D12,Категории!$A$5:$C$17,3,FALSE()),"п. 21 — по пом. "&$E12) -> п. 21 — по пом. 6 | H12: =MAX($F12+15,65) -> 95 | I12: =IF($F12<=65,"упрощённая оценка (п. 6.11.3)","нужен расчёт (прил. В / ПО изготовителя)") -> нужен расчёт (прил. В / ПО изготовителя) | J12: Смежная: 6 слесарная | K12: =VLOOKUP($D12,Категории!$A$5:$C$17,2,FALSE()) -> 60
A13: 1 | B13: 8 | C13: Лестничная клетка | D13: Коммуникационные пространства | F13: =IF($E13="",$K13,MAX($K13,INDEX($K$6:$K$225,MATCH($E13,$B$6:$B$225,0)))) -> 60 | G13: =IF($E13="",VLOOKUP($D13,Категории!$A$5:$C$17,3,FALSE()),"п. 21 — по пом. "&$E13) -> п. 21 | H13: =MAX($F13+15,65) -> 75 | I13: =IF($F13<=65,"упрощённая оценка (п. 6.11.3)","нужен расчёт (прил. В / ПО изготовителя)") -> упрощённая оценка (п. 6.11.3) | K13: =VLOOKUP($D13,Категории!$A$5:$C$17,2,FALSE()) -> 60
A14: 1 | B14: 9 | C14: Подсобное | D14: Вспомогательные помещения | F14: =IF($E14="",$K14,MAX($K14,INDEX($K$6:$K$225,MATCH($E14,$B$6:$B$225,0)))) -> 60 | G14: =IF($E14="",VLOOKUP($D14,Категории!$A$5:$C$17,3,FALSE()),"п. 21 — по пом. "&$E14) -> по аналогии с п. 6 | H14: =MAX($F14+15,65) -> 75 | I14: =IF($F14<=65,"упрощённая оценка (п. 6.11.3)","нужен расчёт (прил. В / ПО изготовителя)") -> упрощённая оценка (п. 6.11.3) | K14: =VLOOKUP($D14,Категории!$A$5:$C$17,2,FALSE()) -> 60
A15: 1 | B15: 10 | C15: Подсобное | D15: Вспомогательные помещения | F15: =IF($E15="",$K15,MAX($K15,INDEX($K$6:$K$225,MATCH($E15,$B$6:$B$225,0)))) -> 60 | G15: =IF($E15="",VLOOKUP($D15,Категории!$A$5:$C$17,3,FALSE()),"п. 21 — по пом. "&$E15) -> по аналогии с п. 6 | H15: =MAX($F15+15,65) -> 75 | I15: =IF($F15<=65,"упрощённая оценка (п. 6.11.3)","нужен расчёт (прил. В / ПО изготовителя)") -> упрощённая оценка (п. 6.11.3) | K15: =VLOOKUP($D15,Категории!$A$5:$C$17,2,FALSE()) -> 60
A16: 1 | B16: 11 | C16: Подсобное | D16: Вспомогательные помещения | F16: =IF($E16="",$K16,MAX($K16,INDEX($K$6:$K$225,MATCH($E16,$B$6:$B$225,0)))) -> 60 | G16: =IF($E16="",VLOOKUP($D16,Категории!$A$5:$C$17,3,FALSE()),"п. 21 — по пом. "&$E16) -> по аналогии с п. 6 | H16: =MAX($F16+15,65) -> 75 | I16: =IF($F16<=65,"упрощённая оценка (п. 6.11.3)","нужен расчёт (прил. В / ПО изготовителя)") -> упрощённая оценка (п. 6.11.3) | K16: =VLOOKUP($D16,Категории!$A$5:$C$17,2,FALSE()) -> 60
A17: 1 | B17: 12 | C17: Подсобное | D17: Вспомогательные помещения | F17: =IF($E17="",$K17,MAX($K17,INDEX($K$6:$K$225,MATCH($E17,$B$6:$B$225,0)))) -> 60 | G17: =IF($E17="",VLOOKUP($D17,Категории!$A$5:$C$17,3,FALSE()),"п. 21 — по пом. "&$E17) -> по аналогии с п. 6 | H17: =MAX($F17+15,65) -> 75 | I17: =IF($F17<=65,"упрощённая оценка (п. 6.11.3)","нужен расчёт (прил. В / ПО изготовителя)") -> упрощённая оценка (п. 6.11.3) | K17: =VLOOKUP($D17,Категории!$A$5:$C$17,2,FALSE()) -> 60
A18: 1 | B18: 13 | C18: Подсобное | D18: Вспомогательные помещения | F18: =IF($E18="",$K18,MAX($K18,INDEX($K$6:$K$225,MATCH($E18,$B$6:$B$225,0)))) -> 60 | G18: =IF($E18="",VLOOKUP($D18,Категории!$A$5:$C$17,3,FALSE()),"п. 21 — по пом. "&$E18) -> по аналогии с п. 6 | H18: =MAX($F18+15,65) -> 75 | I18: =IF($F18<=65,"упрощённая оценка (п. 6.11.3)","нужен расчёт (прил. В / ПО изготовителя)") -> упрощённая оценка (п. 6.11.3) | K18: =VLOOKUP($D18,Категории!$A$5:$C$17,2,FALSE()) -> 60
A19: 1 | B19: 14 | C19: Подсобное | D19: Вспомогательные помещения | F19: =IF($E19="",$K19,MAX($K19,INDEX($K$6:$K$225,MATCH($E19,$B$6:$B$225,0)))) -> 60 | G19: =IF($E19="",VLOOKUP($D19,Категории!$A$5:$C$17,3,FALSE()),"п. 21 — по пом. "&$E19) -> по аналогии с п. 6 | H19: =MAX($F19+15,65) -> 75 | I19: =IF($F19<=65,"упрощённая оценка (п. 6.11.3)","нужен расчёт (прил. В / ПО изготовителя)") -> упрощённая оценка (п. 6.11.3) | K19: =VLOOKUP($D19,Категории!$A$5:$C$17,2,FALSE()) -> 60
A20: 1 | B20: 15 | C20: Подсобное | D20: Вспомогательные помещения | F20: =IF($E20="",$K20,MAX($K20,INDEX($K$6:$K$225,MATCH($E20,$B$6:$B$225,0)))) -> 60 | G20: =IF($E20="",VLOOKUP($D20,Категории!$A$5:$C$17,3,FALSE()),"п. 21 — по пом. "&$E20) -> по аналогии с п. 6 | H20: =MAX($F20+15,65) -> 75 | I20: =IF($F20<=65,"упрощённая оценка (п. 6.11.3)","нужен расчёт (прил. В / ПО изготовителя)") -> упрощённая оценка (п. 6.11.3) | K20: =VLOOKUP($D20,Категории!$A$5:$C$17,2,FALSE()) -> 60
A21: 1 | B21: 16 | C21: Подсобное | D21: Вспомогательные помещения | F21: =IF($E21="",$K21,MAX($K21,INDEX($K$6:$K$225,MATCH($E21,$B$6:$B$225,0)))) -> 60 | G21: =IF($E21="",VLOOKUP($D21,Категории!$A$5:$C$17,3,FALSE()),"п. 21 — по пом. "&$E21) -> по аналогии с п. 6 | H21: =MAX($F21+15,65) -> 75 | I21: =IF($F21<=65,"упрощённая оценка (п. 6.11.3)","нужен расчёт (прил. В / ПО изготовителя)") -> упрощённая оценка (п. 6.11.3) | K21: =VLOOKUP($D21,Категории!$A$5:$C$17,2,FALSE()) -> 60
A22: 1 | B22: 17 | C22: Коридор | D22: Коммуникационные пространства | F22: =IF($E22="",$K22,MAX($K22,INDEX($K$6:$K$225,MATCH($E22,$B$6:$B$225,0)))) -> 60 | G22: =IF($E22="",VLOOKUP($D22,Категории!$A$5:$C$17,3,FALSE()),"п. 21 — по пом. "&$E22) -> п. 21 | H22: =MAX($F22+15,65) -> 75 | I22: =IF($F22<=65,"упрощённая оценка (п. 6.11.3)","нужен расчёт (прил. В / ПО изготовителя)") -> упрощённая оценка (п. 6.11.3) | K22: =VLOOKUP($D22,Категории!$A$5:$C$17,2,FALSE()) -> 60
A23: 1 | B23: 18 | C23: Кабинет | D23: Учебные помещения | F23: =IF($E23="",$K23,MAX($K23,INDEX($K$6:$K$225,MATCH($E23,$B$6:$B$225,0)))) -> 60 | G23: =IF($E23="",VLOOKUP($D23,Категории!$A$5:$C$17,3,FALSE()),"п. 21 — по пом. "&$E23) -> п. 6 | H23: =MAX($F23+15,65) -> 75 | I23: =IF($F23<=65,"упрощённая оценка (п. 6.11.3)","нужен расчёт (прил. В / ПО изготовителя)") -> упрощённая оценка (п. 6.11.3) | K23: =VLOOKUP($D23,Категории!$A$5:$C$17,2,FALSE()) -> 60
A24: 1 | B24: 19 | C24: Кабинет | D24: Учебные помещения | F24: =IF($E24="",$K24,MAX($K24,INDEX($K$6:$K$225,MATCH($E24,$B$6:$B$225,0)))) -> 60 | G24: =IF($E24="",VLOOKUP($D24,Категории!$A$5:$C$17,3,FALSE()),"п. 21 — по пом. "&$E24) -> п. 6 | H24: =MAX($F24+15,65) -> 75 | I24: =IF($F24<=65,"упрощённая оценка (п. 6.11.3)","нужен расчёт (прил. В / ПО изготовителя)") -> упрощённая оценка (п. 6.11.3) | K24: =VLOOKUP($D24,Категории!$A$5:$C$17,2,FALSE()) -> 60
... A26: 1 | B26: 21 | C26: Кабинет | D26: Учебные помещения | F26: =IF($E26="",$K26,MAX($K26,INDEX($K$6:$K$225,MATCH($E26,$B$6:$B$225,0)))) -> 60 | G26: =IF($E26="",VLOOKUP($D26,Категории!$A$5:$C$17,3,FALSE()),"п. 21 — по пом. "&$E26) -> п. 6 | H26: =MAX($F26+15,65) -> 75 | I26: =IF($F26<=65,"упрощённая оценка (п. 6.11.3)","нужен расчёт (прил. В / ПО изготовителя)") -> упрощённая оценка (п. 6.11.3) | K26: =VLOOKUP($D26,Категории!$A$5:$C$17,2,FALSE()) -> 60
A27: 1 | B27: 22 | C27: Коридор | D27: Коммуникационные пространства | E27: 1 | F27: =IF($E27="",$K27,MAX($K27,INDEX($K$6:$K$225,MATCH($E27,$B$6:$B$225,0)))) -> 65 | G27: =IF($E27="",VLOOKUP($D27,Категории!$A$5:$C$17,3,FALSE()),"п. 21 — по пом. "&$E27) -> п. 21 — по пом. 1 | H27: =MAX($F27+15,65) -> 80 | I27: =IF($F27<=65,"упрощённая оценка (п. 6.11.3)","нужен расчёт (прил. В / ПО изготовителя)") -> упрощённая оценка (п. 6.11.3) | J27: Смежный: 1 тир | K27: =VLOOKUP($D27,Категории!$A$5:$C$17,2,FALSE()) -> 60
A28: 1 | B28: 23 | C28: Коридор | D28: Коммуникационные пространства | F28: =IF($E28="",$K28,MAX($K28,INDEX($K$6:$K$225,MATCH($E28,$B$6:$B$225,0)))) -> 60 | G28: =IF($E28="",VLOOKUP($D28,Категории!$A$5:$C$17,3,FALSE()),"п. 21 — по пом. "&$E28) -> п. 21 | H28: =MAX($F28+15,65) -> 75 | I28: =IF($F28<=65,"упрощённая оценка (п. 6.11.3)","нужен расчёт (прил. В / ПО изготовителя)") -> упрощённая оценка (п. 6.11.3) | K28: =VLOOKUP($D28,Категории!$A$5:$C$17,2,FALSE()) -> 60
A29: 1 | B29: 24 | C29: Кабинет | D29: Учебные помещения | F29: =IF($E29="",$K29,MAX($K29,INDEX($K$6:$K$225,MATCH($E29,$B$6:$B$225,0)))) -> 60 | G29: =IF($E29="",VLOOKUP($D29,Категории!$A$5:$C$17,3,FALSE()),"п. 21 — по пом. "&$E29) -> п. 6 | H29: =MAX($F29+15,65) -> 75 | I29: =IF($F29<=65,"упрощённая оценка (п. 6.11.3)","нужен расчёт (прил. В / ПО изготовителя)") -> упрощённая оценка (п. 6.11.3) | K29: =VLOOKUP($D29,Категории!$A$5:$C$17,2,FALSE()) -> 60
A30: 1 | B30: 25 | C30: Кабинет | D30: Учебные помещения | F30: =IF($E30="",$K30,MAX($K30,INDEX($K$6:$K$225,MATCH($E30,$B$6:$B$225,0)))) -> 60 | G30: =IF($E30="",VLOOKUP($D30,Категории!$A$5:$C$17,3,FALSE()),"п. 21 — по пом. "&$E30) -> п. 6 | H30: =MAX($F30+15,65) -> 75 | I30: =IF($F30<=65,"упрощённая оценка (п. 6.11.3)","нужен расчёт (прил. В / ПО изготовителя)") -> упрощённая оценка (п. 6.11.3) | K30: =VLOOKUP($D30,Категории!$A$5:$C$17,2,FALSE()) -> 60
A31: 1 | B31: 26 | C31: Кабинет | D31: Учебные помещения | F31: =IF($E31="",$K31,MAX($K31,INDEX($K$6:$K$225,MATCH($E31,$B$6:$B$225,0)))) -> 60 | G31: =IF($E31="",VLOOKUP($D31,Категории!$A$5:$C$17,3,FALSE()),"п. 21 — по пом. "&$E31) -> п. 6 | H31: =MAX($F31+15,65) -> 75 | I31: =IF($F31<=65,"упрощённая оценка (п. 6.11.3)","нужен расчёт (прил. В / ПО изготовителя)") -> упрощённая оценка (п. 6.11.3) | K31: =VLOOKUP($D31,Категории!$A$5:$C$17,2,FALSE()) -> 60
A32: 1 | B32: 27 | C32: Кабинет | D32: Учебные помещения | F32: =IF($E32="",$K32,MAX($K32,INDEX($K$6:$K$225,MATCH($E32,$B$6:$B$225,0)))) -> 60 | G32: =IF($E32="",VLOOKUP($D32,Категории!$A$5:$C$17,3,FALSE()),"п. 21 — по пом. "&$E32) -> п. 6 | H32: =MAX($F32+15,65) -> 75 | I32: =IF($F32<=65,"упрощённая оценка (п. 6.11.3)","нужен расчёт (прил. В / ПО изготовителя)") -> упрощённая оценка (п. 6.11.3) | K32: =VLOOKUP($D32,Категории!$A$5:$C$17,2,FALSE()) -> 60
A33: 1 | B33: 28 | C33: Коридор | D33: Коммуникационные пространства | F33: =IF($E33="",$K33,MAX($K33,INDEX($K$6:$K$225,MATCH($E33,$B$6:$B$225,0)))) -> 60 | G33: =IF($E33="",VLOOKUP($D33,Категории!$A$5:$C$17,3,FALSE()),"п. 21 — по пом. "&$E33) -> п. 21 | H33: =MAX($F33+15,65) -> 75 | I33: =IF($F33<=65,"упрощённая оценка (п. 6.11.3)","нужен расчёт (прил. В / ПО изготовителя)") -> упрощённая оценка (п. 6.11.3) | K33: =VLOOKUP($D33,Категории!$A$5:$C$17,2,FALSE()) -> 60
A34: 1 | B34: 29 | C34: Класс | D34: Учебные помещения | F34: =IF($E34="",$K34,MAX($K34,INDEX($K$6:$K$225,MATCH($E34,$B$6:$B$225,0)))) -> 60 | G34: =IF($E34="",VLOOKUP($D34,Категории!$A$5:$C$17,3,FALSE()),"п. 21 — по пом. "&$E34) -> п. 6 | H34: =MAX($F34+15,65) -> 75 | I34: =IF($F34<=65,"упрощённая оценка (п. 6.11.3)","нужен расчёт (прил. В / ПО изготовителя)") -> упрощённая оценка (п. 6.11.3) | K34: =VLOOKUP($D34,Категории!$A$5:$C$17,2,FALSE()) -> 60
A35: 1 | B35: 30 | C35: Зал | D35: Многоцелевые залы | F35: =IF($E35="",$K35,MAX($K35,INDEX($K$6:$K$225,MATCH($E35,$B$6:$B$225,0)))) -> 70 | G35: =IF($E35="",VLOOKUP($D35,Категории!$A$5:$C$17,3,FALSE()),"п. 21 — по пом. "&$E35) -> п. 16 | H35: =MAX($F35+15,65) -> 85 | I35: =IF($F35<=65,"упрощённая оценка (п. 6.11.3)","нужен расчёт (прил. В / ПО изготовителя)") -> нужен расчёт (прил. В / ПО изготовителя) | J35: Назначение уточнить; принят как многоцелевой зал | K35: =VLOOKUP($D35,Категории!$A$5:$C$17,2,FALSE()) -> 70
A36: 1 | B36: 31 | C36: Комната охраны | D36: Пост охраны | F36: =IF($E36="",$K36,MAX($K36,INDEX($K$6:$K$225,MATCH($E36,$B$6:$B$225,0)))) -> 70 | G36: =IF($E36="",VLOOKUP($D36,Категории!$A$5:$C$17,3,FALSE()),"п. 21 — по пом. "&$E36) -> п. 2 | H36: =MAX($F36+15,65) -> 85 | I36: =IF($F36<=65,"упрощённая оценка (п. 6.11.3)","нужен расчёт (прил. В / ПО изготовителя)") -> нужен расчёт (прил. В / ПО изготовителя) | J36: Пожарный пост, аварийный микрофон | K36: =VLOOKUP($D36,Категории!$A$5:$C$17,2,FALSE()) -> 70
A37: 1 | B37: 32 | C37: Коридор | D37: Коммуникационные пространства | E37: 30 | F37: =IF($E37="",$K37,MAX($K37,INDEX($K$6:$K$225,MATCH($E37,$B$6:$B$225,0)))) -> 70 | G37: =IF($E37="",VLOOKUP($D37,Категории!$A$5:$C$17,3,FALSE()),"п. 21 — по пом. "&$E37) -> п. 21 — по пом. 30 | H37: =MAX($F37+15,65) -> 85 | I37: =IF($F37<=65,"упрощённая оценка (п. 6.11.3)","нужен расчёт (прил. В / ПО изготовителя)") -> нужен расчёт (прил. В / ПО изготовителя) | J37: Смежные: 30 зал, 31 комната охраны | K37: =VLOOKUP($D37,Категории!$A$5:$C$17,2,FALSE()) -> 60
A38: 1 | B38: 33 | C38: Тамбур | D38: Коммуникационные пространства | F38: =IF($E38="",$K38,MAX($K38,INDEX($K$6:$K$225,MATCH($E38,$B$6:$B$225,0)))) -> 60 | G38: =IF($E38="",VLOOKUP($D38,Категории!$A$5:$C$17,3,FALSE()),"п. 21 — по пом. "&$E38) -> п. 21 | H38: =MAX($F38+15,65) -> 75 | I38: =IF($F38<=65,"упрощённая оценка (п. 6.11.3)","нужен расчёт (прил. В / ПО изготовителя)") -> упрощённая оценка (п. 6.11.3) | J38: При площади менее 4 м² оповещение можно не предусматривать (п. 6.1.3) | K38: =VLOOKUP($D38,Категории!$A$5:$C$17,2,FALSE()) -> 60
A39: 1 | B39: 34 | C39: Коридор | D39: Коммуникационные пространства | F39: =IF($E39="",$K39,MAX($K39,INDEX($K$6:$K$225,MATCH($E39,$B$6:$B$225,0)))) -> 60 | G39: =IF($E39="",VLOOKUP($D39,Категории!$A$5:$C$17,3,FALSE()),"п. 21 — по пом. "&$E39) -> п. 21 | H39: =MAX($F39+15,65) -> 75 | I39: =IF($F39<=65,"упрощённая оценка (п. 6.11.3)","нужен расчёт (прил. В / ПО изготовителя)") -> упрощённая оценка (п. 6.11.3) | K39: =VLOOKUP($D39,Категории!$A$5:$C$17,2,FALSE()) -> 60
A40: 1 | B40: 36 | C40: Раздевалка | D40: Спортзал, тир, раздевалки | F40: =IF($E40="",$K40,MAX($K40,INDEX($K$6:$K$225,MATCH($E40,$B$6:$B$225,0)))) -> 65 | G40: =IF($E40="",VLOOKUP($D40,Категории!$A$5:$C$17,3,FALSE()),"п. 21 — по пом. "&$E40) -> п. 18 (тир, раздевалки — по аналогии) | H40: =MAX($F40+15,65) -> 80 | I40: =IF($F40<=65,"упрощённая оценка (п. 6.11.3)","нужен расчёт (прил. В / ПО изготовителя)") -> упрощённая оценка (п. 6.11.3) | K40: =VLOOKUP($D40,Категории!$A$5:$C$17,2,FALSE()) -> 65
A41: 1 | B41: 37 | C41: Лестничная клетка | D41: Коммуникационные пространства | F41: =IF($E41="",$K41,MAX($K41,INDEX($K$6:$K$225,MATCH($E41,$B$6:$B$225,0)))) -> 60 | G41: =IF($E41="",VLOOKUP($D41,Категории!$A$5:$C$17,3,FALSE()),"п. 21 — по пом. "&$E41) -> п. 21 | H41: =MAX($F41+15,65) -> 75 | I41: =IF($F41<=65,"упрощённая оценка (п. 6.11.3)","нужен расчёт (прил. В / ПО изготовителя)") -> упрощённая оценка (п. 6.11.3) | K41: =VLOOKUP($D41,Категории!$A$5:$C$17,2,FALSE()) -> 60
A42: 1 | B42: 38 | C42: Коридор | D42: Коммуникационные пространства | E42: 36 | F42: =IF($E42="",$K42,MAX($K42,INDEX($K$6:$K$225,MATCH($E42,$B$6:$B$225,0)))) -> 65 | G42: =IF($E42="",VLOOKUP($D42,Категории!$A$5:$C$17,3,FALSE()),"п. 21 — по пом. "&$E42) -> п. 21 — по пом. 36 | H42: =MAX($F42+15,65) -> 80 | I42: =IF($F42<=65,"упрощённая оценка (п. 6.11.3)","нужен расчёт (прил. В / ПО изготовителя)") -> упрощённая оценка (п. 6.11.3) | J42: Смежная: 36 раздевалка | K42: =VLOOKUP($D42,Категории!$A$5:$C$17,2,FALSE()) -> 60
...

Sheet Категории
A1: Справочник: УЗД постоянного шума по табл. В.1 СП 3.13130.2026
A2: Синие значения в столбце B можно менять — лист «Уровни шума» пересчитается.
A4: Категория помещений | B4: LAeq, дБА | C4: Позиция табл. В.1 | D4: Обоснование
A5: Учебные помещения | B5: 60 | C5: п. 6 | D5: Классные помещения, учебные кабинеты, учительские, читальные залы библиотек
A6: Вспомогательные помещения | B6: 60 | C6: по аналогии с п. 6 | D6: Подсобные, кладовые, склад, архив, инструментальная, бытовка, приёмная — помещения образовательной организации; в табл. В.1 прямой позиции нет
A7: Медицинские помещения | B7: 50 | C7: п. 5 | D7: Кабинеты врачей медицинских организаций
A8: Санузлы | B8: 55 | C8: п. 28 | D8: Ванные, душевые, санузлы
A9: Спортзал, тир, раздевалки | B9: 65 | C9: п. 18 (тир, раздевалки — по аналогии) | D9: Спортивные залы
A10: Обеденный зал | B10: 65 | C10: п. 12 | D10: Залы кафе, ресторанов
A11: Пищеблок | B11: 70 | C11: по аналогии с п. 26 | D11: Кухни ресторанов и кафе (моечная, холодильная камера)
A12: Многоцелевые залы | B12: 70 | C12: п. 16 | D12: Многоцелевые залы (актовый зал, зал)
A13: Пост охраны | B13: 70 | C13: п. 2 | D13: Рабочие помещения диспетчерских служб с речевой связью по телефону
A14: Учебные мастерские со станками | B14: 80 | C14: по аналогии с п. 4 | D14: Помещения с постоянными рабочими местами производственных предприятий; станки учтены как постоянный шум (п. 6.8.7). При автоматическом отключении станков по сигналу «Пожар» не более чем за 60 с принять 60 дБА
A15: Бойлерная | B15: 80 | C15: п. 24 | D15: Помещения компрессорных и насосных (постоянно или попеременно работающих)
A16: Венткамера | B16: 80 | C16: п. 23 | D16: Помещения для вентмашин
A17: Коммуникационные пространства | B17: 60 | C17: п. 21 | D17: Коридоры, лестничные клетки, тамбуры: по уровню шума в помещениях, имеющих прямое сообщение. По умолчанию — учебные помещения (60); если рядом более шумное помещение — по нему (столбец E)

Sheet Пояснения
A1: Пояснения к расчёту уровней шума
A3: Источник
A4: СП 3.13130.2026 (введён с 01.06.2026), приложение В, п. В.2.1 и таблица В.1. УЗД постоянного шума принимается по измерениям или по справочным данным табл. В.1; по заданию на проектирование значения можно корректировать в большую сторону.
A5: Примечание 2 к табл. В.1: фактический УЗД постоянного шума уточняется при вводе системы в эксплуатацию.
A6: П. 6.8.6: уровни постоянного шума должны быть отражены в проектной документации.
A8: Как выбраны значения
A9: 1. Где назначение помещения прямо есть в табл. В.1 — взята эта позиция.
A10: 2. Где прямой позиции нет — ближайшая по смыслу; в спорных случаях выбиралось большее значение (это допускает п. В.2.1).
A11: 3. Коридоры, лестничные клетки, тамбуры (п. 21) — по шуму в смежных помещениях: по умолчанию 60 дБА (учебные помещения); если в коридор выходит более шумное помещение — по нему (лист «Уровни шума», столбец E). Смежность определена по планам листов 6–9.
A12: 4. Мастерские и слесарные приняты 80 дБА: станки считаются постоянным шумом, если их нельзя автоматически остановить при пожаре за 60 с (п. 6.8.7). Если в проект добавить отключение станков по сигналу «Пожар», на листе «Категории» поменять 80 на 60 — мастерские и коридоры 7, 75, 79, 81, 84, 85 пересчитаются. Коридор 4 останется 80 (смежная бойлерная).
A14: Что следует из уровня шума
A15: П. 6.8.2: сигнал оповещения должен превышать постоянный шум не менее чем на 15 дБ и быть не ниже 65 дБА в любой точке на высоте 1,5 м (столбец H).
... A27: • Опечатки в экспликации: 61 «Кооридор», 88 и 156 «Лаборанская».
